Workbook

Sheet 全纸筒核价表
R1: 正规（787*1089）/大规（889*1192）
A2: 东嘉纸罐核价系统（内部使用） | R2: 纸张开数计算器（cm）
A3: 注意：白色框的各种价格和参数要自己输入！灰色部稍做修改，算工资更准。输完按回车就行！ | S3: 长 | T3: 宽
J4: 拉管一小时 ￥/米 | L4: 修头工资 | N4: 封盖：一天填多少次 | S4: 37 | T4: 34
C5: 直径（CM） | D5: 高度（CM） | E5: 数量 | F5: 亚膜0.5/亮膜0.4 | G5: 内管长度 | H5: 内管是1/否0卷边 | I5: 热熔胶￥元/平方 | J5: 1小时工次 | K5: 米数 | L5: 1天工资 | M5: 1天次数 | N5: 1天工资 | O5: 1天次数 | R5: 正规 | S5: =面纸开数!G78 -> 6
C6: 10 | D6: 32.5 | E6: 5000 | F6: 0 | G6: 29 | H6: 0 | I6: 0.7 | J6: 30 | K6: 500 | L6: 200 | M6: 5000 | N6: 350 | O6: 6000 | R6: 大规 | S6: =面纸开数!G70 -> 6
B7: 卷边：一天多少次 | D7: 装配工资 | F7: 纸张开数计算器（cm） | H7: =面纸开数!K39 -> 正规 | I7: 印张拼几个 | J7: 纸张价格设置 | L7: 贴标工资 | N7: 厂租费用 | R7: 正规价格 | S7: 0.9
B8: 1天工资 | C8: 1天次数 | D8: 1天工资 | E8: 1天个数 | F8: 长 | G8: 宽 | H8: =面纸开数!L39 -> 6 | I8: 6 | J8: 大规 | K8: 正规 | L8: 1天工资 | M8: 1天次数 | N8: 1天费用 | O8: 1天个数 | R8: 大规价格 | S8: 1.1
A9: 10 | B9: 30 | C9: 5000 | D9: 450 | E9: 26.5 | F9: 30 | G9: 36 | H9: =面纸开数!M39 -> 0.15 | I9: =H9/I8 -> 0.025 | J9: 1.1 | K9: 0.9 | L9: 200 | M9: 6000 | N9: 1400 | O9: 15000 | T9: 成本：
R10: 更划算是 | S10: =面纸开数!K74 -> 正规 | T10: =面纸开数!M74 -> 0.15
A11: 上下卷边全纸罐 | R11: 印面内有几个 | S11: 2 | T11: =T10/S11 -> 0.075
B12: 纸管成本 | D12: 圆片成本/其它配件 | F12: 面纸 | H12: 纸箱 箱规格（cm） | L12: 工资 | N12: 运费 | W12: 外管每平方/元
B13: 注意： | D13: 注意：纸板4-5元，具体视情况而定 | F13: 纸张费用：用纸张开数器自己算一下填入↑ | L13: 注意：工资要自己社情况输入 | N13: 注意：￥/立方米自己填 | X13: 每平/克重 | Y13: ￥/吨 | Z13: 张数 | AA13: ￥/平方米 | AB13: 损耗率
B14: 外管圆周面积 | C14: =(D6+2)*C6*3.1415/10000 -> 0.10838175 | D14: 圆片面积2片 | E14: =(C6+1)*(C6+1)*2/10000 -> 0.0242 | F14: 单面纸长度（供参考） | G14: =C6*3.1415+1.2+C6+0.8 -> 43.415 | H14: 横排数 | I14: =ROUND(45/C6,0) -> 5 | J14: =C6*I14+1.5 -> 51.5 | K14: CM | L14: 拉管工资 | M14: =J6/K6*(D6+2)/100+J6/K6*(G6+H6)/100 -> 0.0381 | N14: 每箱立方数 | O14: =J14*J15*J16/1000000 -> 0.21220575 | W14: 1 | X14: 180 | Y14: 6500 | Z14: 3 | AA14: =X14*Y14*Z14/1000000 -> 3.51
B15: 外管平方价格 | C15: 4.5 | D15: 纸板￥元/平 | E15: 3.7 | F15: 单面纸宽度（供参考） | G15: =D6+2 -> 34.5 | H15: 坚排数 | I15: =ROUND(55/C6,0) -> 6 | J15: =C6*I15+1.5 -> 61.5 | K15: CM | L15: 切管工资 | M15: 0 | N15: ￥/立方米： | O15: 60 | W15: 2 | X15: 80 | Y15: 5400 | Z15: 1 | AA15: =X15*Y15*Z15/1000000 -> 0.432
B16: 参考价格： | C16: =AA18*AB18 -> 4.5333 | D16: 圆片价格 | E16: =E15*E14 -> 0.08954 | F16: 印面里面能拼几个 | G16: 10 | H16: 高排数 | I16: =ROUND(50/D6,0) -> 2 | J16: =D6*I16+2 -> 67 | K16: CM | L16: 贴标工资 | M16: =L9/M9 -> 0.033333333 | N16: 每箱运费： | O16: =O14*O15 -> 12.732345 | W16: 3 | X16: 130 | Y16: 3500 | Z16: 0 | AA16: =X16*Y16*Z16/1000000 -> 0
B17: 外管价格： | C17: =C15*C14 -> 0.48771788 | D17: 贴+冲压1 | E17: 0.05 | F17: 计算器算的费用 | G17: =I9 -> 0.025 | H17: 装箱总数： | I17: =I16*I15*I14 -> 60 | L17: 卷边工资 | M17: =B9/C9 -> 0.006 | N17: 每个运费： | O17: =O16/I17 -> 0.21220575 | W17: 4 | AA17: =X17*Y17*Z17/1000000 -> 0
B18: 内管圆周面积 | C18: =(C6-0.2)*3.14159*(G6+H6)/10000 -> 0.089283988 | D18: 其它配件1 | E18: 0 | F18: 纸张费用 | G18: 0.03 | H18: 纸箱平方数 | I18: =((J16+J14)*(J15+J14)*2+2)/10000 -> 2.6783 | J18: 3.6 | K18: /平方 | L18: 卷边次数 | M18: =2+H6 -> 2 | Z18: 合计： | AA18: =AA14+AA15+AA16+AA17 -> 3.942 | AB18: 1.15
B19: 每管平方价格 | C19: 4.5 | D19: 其它配件2 | F19: 复膜费用 | G19: =F6*G15*G14/10000 -> 0 | H19: 一个纸箱价格： | I19: =I18*J18 -> 9.64188 | L19: 卷边总费用 | M19: =M18*M17 -> 0.012 | N19: 总方数可用于包车参考 | W19: 内管每平方/元
B20: 参考价格： | C20: =AA24*AB24 -> 4.5333 | D20: 其它配件3 | F20: 印刷费用 | G20: =IF(300/E6<0.03,0.03,300/E6) -> 0.06 | H20: 一个纸罐需： | I20: =I19/I17 -> 0.160698 | L20: 按圆片费用： | M20: 0.05 | N20: 总方数： | O20: =O14*(E6/I17) -> 17.683812 | W20: 1 | X20: 180 | Y20: 6500 | Z20: 3 | AA20: =X20*Y20*Z20/1000000 -> 3.51
B21: 内管价格： | C21: =C19*C18 -> 0.40177795 | D21: 其它配件4 | F21: 烫金 | G21: 0 | L21: 装配费用： | M21: =D9/E9 -> 16.981132 | N21: 包车费用： | O21: 15000 | W21: 2 | X21: 80 | Y21: 5400 | Z21: 1 | AA21: =X21*Y21*Z21/1000000 -> 0.432
D22: 其它配件5 | F22: ＵＶ | L22: 打包工资 | M22: 0.03 | N22: 包车每个费用 | O22: =O21/E6 -> 3 | W22: 3 | AA22: =X22*Y22*Z22/1000000 -> 0
B23: 热熔胶成本 | C23: =C14*I6 -> 0.075867225 | F23: 凸出 | G23: 0 | L23: 厂租+电费： | M23: =N9/O9 -> 0.093333333 | W23: 4 | AA23: =X23*Y23*Z23/1000000 -> 0
L24: 其它费用 | Z24: 合计： | AA24: =AA20+AA21+AA22+AA23 -> 3.942 | AB24: 1.15
L25: 其它费用 | W25: 第三用管每平方/元
L26: 其它费用 | W26: 1 | X26: 180 | Y26: 5000 | Z26: 3 | AA26: =X26*Y26*Z26/1000000 -> 2.7
L27: 合计 | M27: =M14+M15+M16+M19+M20+M21+M22+M23+M24+M25+M26 -> 17.237899 | W27: 2 | X27: 80 | Y27: 5000 | Z27: 1 | AA27: =X27*Y27*Z27/1000000 -> 0.4
C28: 纸管+胶成本 | E28: 圆片+配件 | G28: 面纸 | J28: 纸箱费用 | M28: 加工工资 | O28: 每个运费： | P28: 总成本 | W28: 2 | AA28: =X28*Y28*Z28/1000000 -> 0
B29: 自动成本核算 | C29: =C17+C21+C23 -> 0.96536305 | E29: =E19+0+E17+E16+E18+E20+E21+E22 -> 0.13954 | G29: =G20+G19+G18+G21+G22+G23 -> 0.09 | J29: =I20 -> 0.160698 | M29: =M27 -> 17.237899 | O29: 0 | P29: =ROUND(C29+E29+J29+M29+G29+O29,3) -> 18.593 | W29: 4 | AA29: =X29*Y29*Z29/1000000 -> 0
B30: 手工成本核算 | C30: 0.36 | E30: 0.07 | G30: 0 | J30: 0.03 | M30: 0.35 | O30: 0 | P30: =O30+M30+J30+G30+E30+C30 -> 0.81 | Z30: 合计： | AA30: =AA26+AA27+AA28+AA29 -> 3.1 | AB30: 1.05
J34: 拉管一小时 ￥/米 | L34: 修头工资 | N34: 封盖：一天填多少次
C35: 直径（CM） | D35: 高度（CM） | E35: 数量 | F35: 亚膜0.5/亮膜0.4 | G35: 内管长度 | H35: 内管是1/否0卷边 | I35: 热熔胶￥元/平方 | J35: 1小时工次 | K35: 米数 | L35: 1天工资 | M35: 1天次数 | N35: 1天工资 | O35: 1天次数
C36: 8.5 | D36: 12 | E36: 5000 | F36: 0.5 | G36: 14 | H36: 0 | I36: 0.7 | J36: 30 | K36: 500 | L36: 200 | M36: 5000 | N36: 350 | O36: 6000
B37: 卷边：一天多少次 | D37: 装配工资 | F37: 纸张开数计算器（cm） | H37: =面纸开数!AA39 -> 正规 | I37: 印张拼几个 | J37: 纸张价格设置 | L37: 贴标工资 | N37: 厂租费用
B38: 1天工资 | C38: 1天次数 | D38: 1天工资 | E38: 1天个数 | F38: 长 | G38: 宽 | H38: =面纸开数!AB39 -> 8 | I38: 1 | J38: 大规 | K38: 正规 | L38: 1天工资 | M38: 1天次数 | N38: 1天费用 | O38: 1天个数
B39: 200 | C39: 8000 | D39: 450 | E39: 7000 | F39: 34 | G39: 27 | H39: =面纸开数!AC39 -> 0.1125 | I39: =H39/I38 -> 0.1125 | J39: 1.1 | K39: 0.9 | L39: 200 | M39: 6000 | N39: 1400 | O39: 15000
A40: 天地盖型全纸罐
B41: 纸管成本 | D41: 圆片成本/其它配件 | F41: 面纸 | H41: 纸箱 箱规格（cm） | L41: 工资 | N41: 运费
B42: 注意： | D42: 注意：纸板4-5元，具体视情况而定 | F42: 纸张费用：用纸张开数器自己算一下填入 | H42: 箱板价格3.5-4 | L42: 注意：工资要自己社情况输入 | N42: 注意：￥/立方米自己填
B43: 外管圆周面积 | C43: =(D36+1.5)*C36*3.1415/10000 -> 0.036048713 | D43: 圆片面积 | E43: =(C36+1)*(C36+1)*2/10000 -> 0.01805 | F43: 单面纸长度（供参考） | G43: =C36*3.1415+1.2+C36+0.8 -> 37.20275 | H43: 横排数 | I43: =ROUND(45/C36,0) -> 5 | J43: =C36*I43+1.5 -> 44 | K43: CM | L43: 拉管工资 | M43: =J6/K6*(D6+2)/100+J6/K6*(G6+H6)/100 -> 0.0381 | N43: 每箱立方数 | O43: =J43*J44*J45/1000000 -> 0.1155
...

Sheet 铁盖纸筒核价表
A2: 东嘉纸罐核价系统（内部使用）13566116326
A3: 注意：白色框的各种价格和参数要自己输入！灰色部参数也可调节，算工资更准。输完按回车就行！其它颜色不要点。 | Q3: 纸张开数计算器（mm）
J4: 拉管一小时 ￥/米 | L4: 修头工资 | N4: 封盖：一天填多少次 | R4: 长 | S4: 宽
B5: 铁盖规格查找 | C5: 直径（CM） | D5: 高度（CM） | E5: 数量 | F5: 亚膜0.5/亮膜0.4 | G5: 内管长度 | H5: 内管是1/否0卷边 | I5: 热熔胶￥元/平方 | J5: 1小时工次 | K5: 米数 | L5: 1天工资 | M5: 1天次数 | N5: 1天工资 | O5: 1天次数 | R5: 210 | S5: 190
B6: 94 | C6: 15.2 | D6: 31 | E6: 100000 | F6: 0.5 | G6: 0 | H6: 1 | I6: 0.7 | J6: 30 | K6: 500 | L6: 200 | M6: 5000 | N6: 350 | O6: 6000 | Q6: 正规 | R6: =面纸开数!G107 -> 20
D7: . | Q7: 大规 | R7: =面纸开数!G99 -> 24
A8: 单筒打铁盖 | Q8: 正规价格 | R8: 0.9 | T8: 外管每平方/元
B9: 纸管成本 | D9: 铁盖成本/其它配件 | F9: 面纸 | H9: 纸箱 箱规格（cm） | L9: 工资 | N9: 运费 | Q9: 大规价格 | R9: 1.1 | U9: 每平/克重 | V9: ￥/吨 | W9: 张数 | X9: ￥/平方米 | Y9: 损耗率
B10: 直径 | C10: =C6 -> 15.2 | D10: 底盖参考价 | E10: =AC31 -> #N/A | F10: 注意事项：如果特种纸可以价格/总开数 | H10: 横排数 | I10: =ROUND(45/C6,0) -> 3 | J10: =C6*I10+1.5 -> 47.1 | K10: CM | L10: 注意：工资要自己视情况输入 | N10: 注意：￥/立方米自己填 | S10: 成本： | T10: 1 | U10: 300 | V10: 3000 | W10: 3 | X10: =U10*V10*W10/1000000 -> 2.7
B11: 高度 | C11: =D6 -> 31 | D11: 底盖 | E11: 0.19 | F11: 印面规格： | H11: 坚排数 | I11: =ROUND(55/C6,0) -> 4 | J11: =C6*I11+1.5 -> 62.3 | K11: CM | L11: 拉管工资 | M11: =J6/K6*D6/100 -> 0.0186 | N11: 每箱立方数 | O11: =J10*J11*J12/1000000 -> 0.18779712 | Q11: 更划算是 | R11: =面纸开数!K103 -> 正规 | S11: =面纸开数!M103 -> 0.045 | T11: 2 | U11: 80 | V11: 12000 | W11: 1 | X11: =U11*V11*W11/1000000 -> 0.96
B12: 圆周面积 | C12: =C11*3.14159*C10/10000 -> 0.14803172 | D12: 拉深盖参考价 | E12: =AD31 -> #N/A | F12: 长度 | G12: 宽度 | H12: 高排数 | I12: =ROUND(50/D6,0) -> 2 | J12: =D6*I12+2 -> 64 | K12: CM | L12: 切管工资 | M12: 0 | N12: ￥/立方米： | O12: 60 | T12: 3 | U12: 170 | V12: 5000 | W12: 1 | X12: =U12*V12*W12/1000000 -> 0.85
B13: 每平方价格 | C13: 4.8 | D13: 拉深盖 | E13: 0.25 | F13: =印面价格!K16 -> #DIV/0! | G13: =印面价格!L16 -> #DIV/0! | H13: 装箱总数： | I13: =I12*I11*I10 -> 24 | L13: 贴标工资： | M13: 0.05 | N13: 每箱运费： | O13: =O11*O12 -> 11.267827 | T13: 4 | X13: =U13*V13*W13/1000000 -> 0
B14: 参考价格： | C14: =X14*Y14 -> 4.7355 | D14: 珍珠棉垫 | E14: 0.2 | F14: 本张纸拼几个 | G14: =印面价格!L17 -> #DIV/0! | H14: 纸箱平方数 | I14: =((J12+J10)*(J11+J10)*2+2)/10000 -> 2.431068 | L14: 封盖工资 | M14: =ROUND(N6/O6,3) -> 0.058 | N14: 每个运费： | O14: =O13/I13 -> 0.4694928 | W14: 合计： | X14: =X10+X11+X12+X13 -> 4.51 | Y14: 1.05
B15: 纸管成本： | C15: =C12*C13 -> 0.71055226 | D15: 其它配件1 | E15: 0 | F15: =印面价格!K18 -> #DIV/0! | G15: =印面价格!L18 -> #DIV/0! | H15: 纸箱多少￥/平方 | I15: 3.5 | J15: 3.5-4.5 | L15: 修头工资 | M15: =L6/M6 -> 0.04 | N15: 总方数可用于包车参考 | T15: 内管每平方/元
D16: 其它配件2 | E16: 0 | F16: =印面价格!K20 -> 总共几张： | G16: =印面价格!L20 -> #DIV/0! | H16: 一个纸箱价格： | I16: =I14*I15 -> 8.508738 | L16: 盖盖子工资 | M16: 0.03 | N16: 总方数： | O16: =O11*(E6/I13) -> 782.488 | T16: 1 | U16: 300 | V16: 3000 | W16: 2 | X16: =U16*V16*W16/1000000 -> 1.8
B17: 热熔胶成本 | C17: =C6*3.14159*D6*I6/10000 -> 0.1036222 | D17: 其它配件3 | E17: 0 | F17: 单张参考价格： | G17: =印面价格!L21 -> #DIV/0! | H17: 每个纸管需：￥ | I17: =I16/I13 -> 0.35453075 | L17: 打包工资 | M17: 0.03 | N17: 包车费用： | O17: 55000 | T17: 2 | U17: 60 | V17: 5400 | W17: 2 | X17: =U17*V17*W17/1000000 -> 0.648
F18: 单张价格： | G18: 0.15 | L18: 厂租+电费： | M18: 0.15 | N18: 包车每个费用 | O18: =O17/E6 -> 0.55 | T18: 3 | X18: =U18*V18*W18/1000000 -> 0
F19: 复膜 | G19: =C12*F6 -> 0.07401586 | L19: 其它费用： | T19: 4 | X19: =U19*V19*W19/1000000 -> 0
F20: 印刷 | G20: =IF(E6/G14>=10000,0.03/G14,300/E6) -> #DIV/0! | L20: 其它费用： | W20: 合计： | X20: =X16+X17+X18+X19 -> 2.448 | Y20: 1.05
F21: 烫金 | L21: 其它费用： | T21: 第三用管每平方/元
F22: UV | G22: 0.12 | L22: 总计 | M22: =M11+M12+M14+M15+M16+M13+M18+M19+M20+M21 -> 0.3466 | T22: 1 | U22: 180 | V22: 5000 | W22: 3 | X22: =U22*V22*W22/1000000 -> 2.7
C23: 纸管+胶成本 | E23: 铁盖+配件 | G23: 面纸 | J23: 纸箱成本 | P23: 总成本 | T23: 2 | U23: 80 | V23: 5000 | W23: 1 | X23: =U23*V23*W23/1000000 -> 0.4
B24: 自动成本核算 | C24: =C13*C12+C17 -> 0.81417446 | E24: =E14+E13+E11+E15+E16+E17 -> 0.64 | G24: =TRUNC(G18+G19+G20+G21+G22,4) -> #DIV/0! | J24: =TRUNC(I17,4) -> 0.3545 | M24: =TRUNC(M11+M12+M14+M15+M16+M13+M18,4) -> 0.3466 | O24: 0 | P24: =ROUND(C24+E24+G24+J24+M24+O24,3) -> #DIV/0! | T24: 2 | X24: =U24*V24*W24/1000000 -> 0
B25: 手工成本核算 | C25: 0.5 | E25: 0.64 | G25: 0.42 | J25: 0.22 | M25: 0.34 | O25: 0.04 | P25: =O25+M25+J25+G25+E25+C25 -> 2.16 | T25: 4 | X25: =U25*V25*W25/1000000 -> 0
B26: 有一些项目需要手工计算（大部分可参考自动核算的） | W26: 合计： | X26: =X22+X23+X24+X25 -> 3.1 | Y26: 1.05
B29: 卷边工资 | D29: 装配工资 | AA29: 铁盖价格
B30: 1天工资 | C30: 1天次数 | D30: 1天工资 | E30: 1天数量 | AB30: 直径 | AC30: 底盖价格 | AD30: 拉深盖价格
B31: 200 | C31: 5000 | D31: 450 | E31: 6000 | AB31: =C6*10 -> 152 | AC31: =VLOOKUP(AB31,Sheet2!$B$3:$F$37,2,FALSE) -> #N/A | AD31: =VLOOKUP(AB31,Sheet2!$B$3:$F$37,4,FALSE) -> #N/A
U32: 型号 | V32: 单价（金银色） | Z32: 单价（黑金色） | AF32: 单价（黑银色） | AI32: 子母口（金银色）三件套
A33: 上下马口铁盖纸罐 | T33: 手工查找（mm）
B34: 纸管成本 | D34: 铁盖成本/其它配件 | F34: 面纸 | H34: 纸箱 箱规格（cm） | L34: 工资 | N34: 运费 | U34: 94 | V34: =VLOOKUP(U34,Sheet2!$B$3:$R$37,2,FALSE) -> 0.17元 | W34: 拉伸盖 | X34: =VLOOKUP(U34,Sheet2!$B$3:$R$37,4,FALSE) -> 0.23元 | Z34: 黑底盖 | AA34: =VLOOKUP(U34,Sheet2!$B$3:$R$37,7,FALSE) -> 0.19元 | AB34: 黑拉深 | AC34: =VLOOKUP(U34,Sheet2!$B$3:$R$37,9,FALSE) -> 0.25元 | AF34: =VLOOKUP(U34,Sheet2!$B$3:$R$37,12,FALSE) -> 0.19元 | AH34: =VLOOKUP(U34,Sheet2!$B$3:$R$37,14,FALSE) -> 0.25元 | AK34: =VLOOKUP(U34,Sheet2!$B$3:$R$37,17,FALSE) -> 0
B35: 注意： | D35: 注意：纸板4-5元，具体视情况而定 | F35: 注意：如果特种纸可以价格/总开数 | L35: 注意：工资要自己社情况输入 | N35: 注意：￥/立方米自己填 | U35: 145 | V35: =VLOOKUP(U35,Sheet2!$B$3:$R$37,2,FALSE) -> 0.41元 | W35: 拉伸盖 | X35: =VLOOKUP(U35,Sheet2!$B$3:$R$37,4,FALSE) -> 0 | Z35: 黑底盖 | AA35: =VLOOKUP(U35,Sheet2!$B$3:$R$37,7,FALSE) -> 0.45元 | AB35: 黑拉深 | AC35: =VLOOKUP(U35,Sheet2!$B$3:$R$37,9,FALSE) -> 0 | AF35: =VLOOKUP(U35,Sheet2!$B$3:$R$37,12,FALSE) -> 0.45元 | AH35: =VLOOKUP(U35,Sheet2!$B$3:$R$37,14,FALSE) -> 0 | AK35: =VLOOKUP(U35,Sheet2!$B$3:$R$37,17,FALSE) -> 1.03元
B36: 外管圆周面积 | C36: =(D6+0)*C6*3.1415/10000 -> 0.14802748 | D36: 铁盖参考价 | E36: =AC31 -> #N/A | F36: 印面规格： | H36: 横排数 | I36: =ROUND(45/C6,0) -> 3 | J36: =C6*I36+1.5 -> 47.1 | K36: CM | L36: 拉管工资 | M36: =J6/K6*(D6+2)/100+J6/K6*(G6+H6)/100 -> 0.0204 | N36: 每箱立方数 | O36: =J36*J37*J38/1000000 -> 0.18779712
B37: 外管平方价格 | C37: 4.1 | D37: 上盖价格 | E37: 0.17 | F37: 长度 | G37: 宽度 | H37: 坚排数 | I37: =ROUND(55/C6,0) -> 4 | J37: =C6*I37+1.5 -> 62.3 | K37: CM | L37: 切管工资 | M37: 0.03 | N37: ￥/立方米： | O37: 50
B38: 参考价格： | C38: =X14*Y14 -> 4.7355 | D38: 下盖价格 | E38: 0.17 | F38: =印面价格!K16 -> #DIV/0! | G38: =印面价格!L16 -> #DIV/0! | H38: 高排数 | I38: =ROUND(50/D6,0) -> 2 | J38: =D6*I38+2 -> 64 | K38: CM | L38: 贴标工资： | M38: 0.04 | N38: 每箱运费： | O38: =O36*O37 -> 9.389856
B39: 外管价格： | C39: =C37*C36 -> 0.60691267 | F39: =印面价格!K17 -> 拼几个： | G39: =印面价格!L17 -> #DIV/0! | H39: 装箱总数： | I39: =I38*I37*I36 -> 24 | L39: 封盖工资2个 | M39: =N6/O6*2 -> 0.11666667 | N39: 每个运费： | O39: =O38/I39 -> 0.391244
B40: 内管圆周面积 | C40: =(C6-0.2)*3.14159*(G6+H6)/10000 -> 0.004712385 | D40: 其它配件1 | E40: 0 | F40: =印面价格!K18 -> #DIV/0! | G40: =印面价格!L18 -> #DIV/0! | H40: 纸箱平方数 | I40: =((J38+J36)*(J37+J36)*2+2)/10000 -> 2.431068 | J40: 4 | K40: /平方 | L40: 切盖工资： | M40: 0.03 | T40: 产品类型 | U40: 型号 | V40: 单价（金银色） | Z40: 单价（黑金色） | AF40: 单价（黑银色） | AI40: 子母口（金银色）三件套
B41: 每管平方价格 | C41: 2.6 | D41: 其它配件2 | F41: =印面价格!K20 -> 总共几张： | G41: =印面价格!L20 -> #DIV/0! | H41: 一个纸箱价格： | I41: =I40*J40 -> 9.724272 | L41: 内管卷边工资： | M41: =H6*B31/C31 -> 0.04 | N41: 总方数可用于包车参考 | T41: 平底 | U41: 33平底 | V41: 0.05元 | Z41: 33黑底 | AA41: 0.06元 | AE41: 33黑底 | AF41: 0.06元
B42: 参考价格： | C42: =X20*Y20 -> 2.5704 | D42: 其它配件3 | F42: 单张参考价格： | G42: =印面价格!L21 -> #DIV/0! | H42: 一个纸罐需： | I42: =I41/I39 -> 0.405178 | L42: 装配工资： | M42: =D31/E31 -> 0.075 | N42: 总方数： | O42: =O36*(E6/I39) -> 782.488 | T42: 扣盖 | U42: 40平底 | V42: 0.06元 | W42: 拉伸盖 | X42: 0.10元 | Z42: 40黑底 | AA42: 0.07元 | AB42: 拉伸盖 | AC42: 0.11元 | AE42: 40黑底 | AF42: 0.07元 | AG42: 拉伸盖 | AH42: 0.11元
B43: 内管价格： | C43: =C41*C40 -> 0.012252201 | D43: 其它配件4 | F43: 单张价格： | G43: 0.15 | L43: 打包工资： | M43: 0.03 | N43: 包车费用： | O43: 15000 | T43: 子母口 | U43: 43平底 | V43: 0.065元 | Z43: 43黑底 | AA43: 0.075元 | AE43: 43黑底 | AF43: 0.075元
...

Sheet Sheet2
A3: 产品类型 | B3: 型号 | C3: 单价（金银色） | G3: 单价（黑金色） | M3: 单价（黑银色） | P3: 子母口（金银色）三件套
A4: 平底 | B4: 33 | C4: 0.05元 | G4: 33黑底 | H4: 0.06元 | L4: 33黑底 | M4: 0.06元
A5: 扣盖 | B5: 40 | C5: 0.06元 | D5: 拉伸盖 | E5: 0.10元 | G5: 40黑底 | H5: 0.07元 | I5: 拉伸盖 | J5: 0.11元 | L5: 40黑底 | M5: 0.07元 | N5: 拉伸盖 | O5: 0.11元
A6: 子母口 | B6: 43 | C6: 0.065元 | G6: 43黑底 | H6: 0.075元 | L6: 43黑底 | M6: 0.075元
B7: 45 | C7: 0.08元 | D7: 拉伸盖 | E7: 0.11元 | G7: 45黑底 | H7: 0.08元 | I7: 拉伸盖 | J7: 0.12元 | L7: 45黑底 | M7: 0.08元 | N7: 拉伸盖 | O7: 0.12元
B8: 46 | C8: 0.055元 | D8: 拉伸盖 | E8: 0.075元 | G8: 46黑底 | H8: 0.065元 | I8: 拉伸盖 | J8: 0.085元 | L8: 46黑底 | M8: 0.065元 | N8: 拉伸盖 | O8: 0.085元
B9: 52 | C9: 0.075元 | D9: 拉伸盖 | E9: 0.10元 | G9: 52黑底 | H9: 0.08元 | I9: 拉伸盖 | J9: 0.12元 | L9: 52黑底 | M9: 0.08元 | N9: 拉伸盖 | O9: 0.12元
B10: 53 | C10: 0.085元 | D10: 拉伸盖 | E10: 0.12元 | G10: 53黑底 | H10: 0.09元 | I10: 拉伸盖 | J10: 0.13元 | L10: 53黑底 | M10: 0.09元 | N10: 拉伸盖 | O10: 0.13元
B11: 56 | C11: 0.095元 | D11: 拉伸盖 | E11: 0.13元 | G11: 56黑底 | H11: 0.10元 | I11: 拉伸盖 | J11: 0.14元 | L11: 56黑底 | M11: 0.10元 | N11: 拉伸盖 | O11: 0.14元
B12: 60 | C12: 0.105元 | D12: 拉伸盖 | E12: 0.13元 | G12: 60黑底 | H12: 0.11元 | I12: 拉伸盖 | J12: 0.14元 | L12: 60黑底 | M12: 0.11元 | N12: 拉伸盖 | O12: 0.14元
B13: 63 | C13: 0.105元 | D13: 拉伸盖 | E13: 0.15元 | G13: 63黑底 | H13: 0.11元 | I13: 拉伸盖 | J13: 0.16元 | L13: 63黑底 | M13: 0.11元 | N13: 拉伸盖 | O13: 0.16元
B14: 65 | C14: 0.105元 | D14: 拉伸盖 | E14: 0.15元 | G14: 65黑底 | H14: 0.11元 | I14: 拉伸盖 | J14: 0.16元 | L14: 65黑底 | M14: 0.11元 | N14: 拉伸盖 | O14: 0.16元
B15: 68 | C15: 0.115元 | G15: 68黑底 | H15: 0.12元 | L15: 68黑底 | M15: 0.12元
B16: 73 | C16: 0.11元 | D16: 拉伸盖 | E16: 0.17元 | G16: 73黑底 | H16: 0.12元 | I16: 拉伸盖 | J16: 0.18元 | L16: 73黑底 | M16: 0.12元 | N16: 拉伸盖 | O16: 0.18元 | Q16: 73子母盖 | R16: 0.38元
B17: 76 | C17: 0.125元 | D17: 拉伸盖 | E17: 0.18元 | G17: 76黑底 | H17: 0.13元 | I17: 拉伸盖 | J17: 0.19元 | L17: 76黑底 | M17: 0.13元 | N17: 拉伸盖 | O17: 0.19元 | Q17: 76子母盖 | R17: 0.40元
B18: 78 | C18: 0.125元 | D18: 拉伸盖 | E18: 0.18元 | G18: 78黑底 | H18: 0.13元 | I18: 拉伸盖 | J18: 0.19元 | L18: 78黑底 | M18: 0.13元 | N18: 拉伸盖 | O18: 0.19元 | Q18: 78子母盖 | R18: 0.42元
B19: 80 | C19: 0.14元 | D19: 拉伸盖 | E19: 0.19元 | G19: 80黑底 | H19: 0.14元 | I19: 拉伸盖 | J19: 0.20元 | L19: 80黑底 | M19: 0.14元 | N19: 拉伸盖 | O19: 0.20元
B20: 82 | C20: 0.14元 | G20: 82黑底 | H20: 0.14元 | L20: 82黑底 | M20: 0.14元
B21: 83 | C21: 0.13元 | D21: 拉伸盖 | E21: 0.18元 | G21: 83黑底 | H21: 0.15元 | I21: 拉伸盖 | J21: 0.20元 | L21: 83黑底 | M21: 0.15元 | N21: 拉伸盖 | O21: 0.20元 | Q21: 83子母盖 | R21: 0.45元
B22: 86 | D22: 拉伸盖 | E22: 0.21元 | G22: 86黑底 | I22: 拉伸盖 | J22: 0.23元 | L22: 86黑底 | N22: 拉伸盖 | O22: 0.23元
B23: 89 | C23: 0.15元 | D23: 拉伸盖 | E23: 0.21元 | G23: 89黑底 | H23: 0.17元 | I23: 拉伸盖 | J23: 0.23元 | L23: 89黑底 | M23: 0.17元 | N23: 拉伸盖 | O23: 0.23元 | Q23: 89子母盖 | R23: 0.46元
B24: 92 | C24: 0.16元 | D24: 拉伸盖 | E24: 0.22元 | G24: 92黑底 | H24: 0.18元 | I24: 拉伸盖 | J24: 0.24元 | L24: 92黑底 | M24: 0.18元 | N24: 拉伸盖 | O24: 0.24元
B25: 94 | C25: 0.17元 | D25: 拉伸盖 | E25: 0.23元 | G25: 94黑底 | H25: 0.19元 | I25: 拉伸盖 | J25: 0.25元 | L25: 94黑底 | M25: 0.19元 | N25: 拉伸盖 | O25: 0.25元
B26: 99 | C26: 0.17元 | D26: 拉伸盖 | E26: 0.24元 | G26: 99黑底 | H26: 0.19元 | I26: 拉伸盖 | J26: 0.27元 | L26: 99黑底 | M26: 0.19元 | N26: 拉伸盖 | O26: 0.27元 | Q26: 99子母盖 | R26: 0.55元
B27: 105 | C27: 0.215元 | D27: 拉伸盖 | E27: 0.28元 | G27: 105黑底 | H27: 0.23元 | I27: 拉伸盖 | J27: 0.31元 | L27: 105黑底 | M27: 0.23元 | N27: 拉伸盖 | O27: 0.31元
B28: 110 | C28: 0.235元 | D28: 拉伸盖 | E28: 0.30元 | G28: 110黑底 | H28: 0.25元 | I28: 拉伸盖 | J28: 0.33元 | L28: 110黑底 | M28: 0.25元 | N28: 拉伸盖 | O28: 0.33元 | Q28: 115子母盖 | R28: 0.76元
B29: 115 | C29: 0.26元 | D29: 拉伸盖 | E29: 0.32元 | G29: 115黑底 | H29: 0.27元 | I29: 拉伸盖 | J29: 0.35元 | L29: 115黑底 | M29: 0.27元 | N29: 拉伸盖 | O29: 0.35元 | Q29: 120子母盖 | R29: 0.78元
B30: 120 | C30: 0.28元 | D30: 拉伸盖 | E30: 0.34元 | G30: 120黑底 | H30: 0.29元 | I30: 拉伸盖 | J30: 0.37元 | L30: 120黑底 | M30: 0.29元 | N30: 拉伸盖 | O30: 0.37元 | Q30: 126子母盖 | R30: 0.80元
B31: 126 | C31: 0.30元 | D31: 拉伸盖 | E31: 0.36元 | G31: 126黑底 | H31: 0.30元 | I31: 拉伸盖 | J31: 0.39元 | L31: 126黑底 | M31: 0.30元 | N31: 拉伸盖 | O31: 0.39元
B32: 140 | C32: 0.38元 | G32: 140黑底 | H32: 0.38元 | L32: 140黑底 | M32: 0.38元 | Q32: 140子母盖 | R32: 1元
B33: 145 | C33: 0.41元 | G33: 145黑底 | H33: 0.45元 | L33: 145黑底 | M33: 0.45元 | Q33: 145子母盖 | R33: 1.03元
B34: 153 | C34: 0.46元 | D34: 拉伸盖 | E34: 0.55元 | G34: 153黑底 | H34: 0.48元 | I34: 拉伸盖 | J34: 0.62元 | L34: 153黑底 | M34: 0.48元 | N34: 拉伸盖 | O34: 0.62元 | Q34: 153子母盖 | R34: 1.23元
B35: 160 | C35: 0.64元 | G35: 160黑底 | H35: 0.67元 | L35: 160黑底 | M35: 0.67元
B36: 174 | C36: 1元 | G36: 174黑底 | H36: 1.05元 | L36: 174黑底 | M36: 1.05元 | Q36: 174子母盖 | R36: 2.25元
B37: 200 | C37: 1.17元 | G37: 200黑底 | H37: 1.2元 | L37: 200黑底 | M37: 1.2元 | Q37: 200子母盖 | R37: 3元

Sheet 铁盖价格表
A1: 报价表
A2: 报价单位：河北省唐山市丰南区海达五金加工厂 联系人：毕海坡 联系电话：15031888917 邮箱：761236828@qq.com
A3: 产品类型 | B3: 型号 | C3: 单价（金银色） | G3: 单价（黑金色） | M3: 单价（黑银色）
A4: 平底 | B4: 33平底 | C4: 0.05元 | G4: 33黑底 | H4: 0.06元 | L4: 33黑底 | M4: 0.06元
A5: 扣盖 | B5: 40平底 | C5: 0.06元 | D5: 拉伸盖 | E5: 0.10元 | G5: 40黑底 | H5: 0.07元 | I5: 拉伸盖 | J5: 0.11元 | L5: 40黑底 | M5: 0.07元 | N5: 拉伸盖 | O5: 0.11元
A6: 子母口 | B6: 43平底 | C6: 0.065元 | G6: 43黑底 | H6: 0.075元 | L6: 43黑底 | M6: 0.075元
B7: 45平底 | C7: 0.08元 | D7: 拉伸盖 | E7: 0.11元 | G7: 45黑底 | H7: 0.08元 | I7: 拉伸盖 | J7: 0.12元 | L7: 45黑底 | M7: 0.08元 | N7: 拉伸盖 | O7: 0.12元
B8: 46平底 | C8: 0.055元 | D8: 拉伸盖 | E8: 0.075元 | G8: 46黑底 | H8: 0.065元 | I8: 拉伸盖 | J8: 0.085元 | L8: 46黑底 | M8: 0.065元 | N8: 拉伸盖 | O8: 0.085元
B9: 52平底 | C9: 0.075元 | D9: 拉伸盖 | E9: 0.10元 | G9: 52黑底 | H9: 0.08元 | I9: 拉伸盖 | J9: 0.12元 | L9: 52黑底 | M9: 0.08元 | N9: 拉伸盖 | O9: 0.12元
B10: 53平底 | C10: 0.085元 | D10: 拉伸盖 | E10: 0.12元 | G10: 53黑底 | H10: 0.09元 | I10: 拉伸盖 | J10: 0.13元 | L10: 53黑底 | M10: 0.09元 | N10: 拉伸盖 | O10: 0.13元
B11: 56平底 | C11: 0.095元 | D11: 拉伸盖 | E11: 0.13元 | G11: 56黑底 | H11: 0.10元 | I11: 拉伸盖 | J11: 0.14元 | L11: 56黑底 | M11: 0.10元 | N11: 拉伸盖 | O11: 0.14元
B12: 60平底 | C12: 0.105元 | D12: 拉伸盖 | E12: 0.13元 | G12: 60黑底 | H12: 0.11元 | I12: 拉伸盖 | J12: 0.14元 | L12: 60黑底 | M12: 0.11元 | N12: 拉伸盖 | O12: 0.14元
B13: 63平底 | C13: 0.105元 | D13: 拉伸盖 | E13: 0.15元 | G13: 63黑底 | H13: 0.11元 | I13: 拉伸盖 | J13: 0.16元 | L13: 63黑底 | M13: 0.11元 | N13: 拉伸盖 | O13: 0.16元
B14: 65平底 | C14: 0.105元 | D14: 拉伸盖 | E14: 0.15元 | G14: 65黑底 | H14: 0.11元 | I14: 拉伸盖 | J14: 0.16元 | L14: 65黑底 | M14: 0.11元 | N14: 拉伸盖 | O14: 0.16元
B15: 68平底 | C15: 0.115元 | G15: 68黑底 | H15: 0.12元 | L15: 68黑底 | M15: 0.12元
B16: 73平底 | C16: 0.11元 | D16: 拉伸盖 | E16: 0.17元 | G16: 73黑底 | H16: 0.12元 | I16: 拉伸盖 | J16: 0.18元 | L16: 73黑底 | M16: 0.12元 | N16: 拉伸盖 | O16: 0.18元 | Q16: 73子母盖 | R16: 0.38元
B17: 76平底 | C17: 0.125元 | D17: 拉伸盖 | E17: 0.18元 | G17: 76黑底 | H17: 0.13元 | I17: 拉伸盖 | J17: 0.19元 | L17: 76黑底 | M17: 0.13元 | N17: 拉伸盖 | O17: 0.19元 | Q17: 76子母盖 | R17: 0.40元
B18: 78平底 | C18: 0.125元 | D18: 拉伸盖 | E18: 0.18元 | G18: 78黑底 | H18: 0.13元 | I18: 拉伸盖 | J18: 0.19元 | L18: 78黑底 | M18: 0.13元 | N18: 拉伸盖 | O18: 0.19元 | Q18: 78子母盖 | R18: 0.42元
B19: 80平底 | C19: 0.14元 | D19: 拉伸盖 | E19: 0.19元 | G19: 80黑底 | H19: 0.14元 | I19: 拉伸盖 | J19: 0.20元 | L19: 80黑底 | M19: 0.14元 | N19: 拉伸盖 | O19: 0.20元 | Q19: 83子母盖 | R19: 0.45元
B20: 82平底 | C20: 0.14元 | G20: 82黑底 | H20: 0.14元 | L20: 82黑底 | M20: 0.14元 | Q20: 89子母盖 | R20: 0.46元
B21: 83平底 | C21: 0.13元 | D21: 拉伸盖 | E21: 0.18元 | G21: 83黑底 | H21: 0.15元 | I21: 拉伸盖 | J21: 0.20元 | L21: 83黑底 | M21: 0.15元 | N21: 拉伸盖 | O21: 0.20元 | Q21: 99子母盖 | R21: 0.55元
B22: 86平底 | D22: 拉伸盖 | E22: 0.21元 | G22: 86黑底 | I22: 拉伸盖 | J22: 0.23元 | L22: 86黑底 | N22: 拉伸盖 | O22: 0.23元 | Q22: 115子母盖 | R22: 0.76元
B23: 89平底 | C23: 0.15元 | D23: 拉伸盖 | E23: 0.21元 | G23: 89黑底 | H23: 0.17元 | I23: 拉伸盖 | J23: 0.23元 | L23: 89黑底 | M23: 0.17元 | N23: 拉伸盖 | O23: 0.23元 | Q23: 120子母盖 | R23: 0.78元
B24: 92平底 | C24: 0.16元 | D24: 拉伸盖 | E24: 0.22元 | G24: 92黑底 | H24: 0.18元 | I24: 拉伸盖 | J24: 0.24元 | L24: 92黑底 | M24: 0.18元 | N24: 拉伸盖 | O24: 0.24元 | Q24: 126子母盖 | R24: 0.80元
B25: 94平底 | C25: 0.17元 | D25: 拉伸盖 | E25: 0.23元 | G25: 94黑底 | H25: 0.19元 | I25: 拉伸盖 | J25: 0.25元 | L25: 94黑底 | M25: 0.19元 | N25: 拉伸盖 | O25: 0.25元 | Q25: 140子母盖 | R25: 1元
B26: 99平底 | C26: 0.17元 | D26: 拉伸盖 | E26: 0.24元 | G26: 99黑底 | H26: 0.19元 | I26: 拉伸盖 | J26: 0.27元 | L26: 99黑底 | M26: 0.19元 | N26: 拉伸盖 | O26: 0.27元 | Q26: 145子母盖 | R26: 1.03元
B27: 105平底 | C27: 0.215元 | D27: 拉伸盖 | E27: 0.28元 | G27: 105黑底 | H27: 0.23元 | I27: 拉伸盖 | J27: 0.31元 | L27: 105黑底 | M27: 0.23元 | N27: 拉伸盖 | O27: 0.31元 | Q27: 153子母盖 | R27: 1.23元
B28: 110平底 | C28: 0.235元 | D28: 拉伸盖 | E28: 0.30元 | G28: 110黑底 | H28: 0.25元 | I28: 拉伸盖 | J28: 0.33元 | L28: 110黑底 | M28: 0.25元 | N28: 拉伸盖 | O28: 0.33元 | Q28: 174子母盖 | R28: 2.25元
B29: 115平底 | C29: 0.26元 | D29: 拉伸盖 | E29: 0.32元 | G29: 115黑底 | H29: 0.27元 | I29: 拉伸盖 | J29: 0.35元 | L29: 115黑底 | M29: 0.27元 | N29: 拉伸盖 | O29: 0.35元 | Q29: 200子母盖 | R29: 3元
B30: 120平底 | C30: 0.28元 | D30: 拉伸盖 | E30: 0.34元 | G30: 120黑底 | H30: 0.29元 | I30: 拉伸盖 | J30: 0.37元 | L30: 120黑底 | M30: 0.29元 | N30: 拉伸盖 | O30: 0.37元
B31: 126平底 | C31: 0.30元 | D31: 拉伸盖 | E31: 0.36元 | G31: 126黑底 | H31: 0.30元 | I31: 拉伸盖 | J31: 0.39元 | L31: 126黑底 | M31: 0.30元 | N31: 拉伸盖 | O31: 0.39元
B32: 140平底 | C32: 0.38元 | G32: 140黑底 | H32: 0.38元 | L32: 140黑底 | M32: 0.38元
B33: 145平底 | C33: 0.41元 | G33: 145黑底 | H33: 0.45元 | L33: 145黑底 | M33: 0.45元
B34: 153平底 | C34: 0.46元 | D34: 拉伸盖 | E34: 0.55元 | G34: 153黑底 | H34: 0.48元 | I34: 拉伸盖 | J34: 0.62元 | L34: 153黑底 | M34: 0.48元 | N34: 拉伸盖 | O34: 0.62元
B35: 160平底 | C35: 0.64元 | G35: 160黑底 | H35: 0.67元 | L35: 160黑底 | M35: 0.67元
B36: 174平底 | C36: 1元 | G36: 174黑底 | H36: 1.05元 | L36: 174黑底 | M36: 1.05元
B37: 200平底 | C37: 1.17元 | G37: 200黑底 | H37: 1.2元 | L37: 200黑底 | M37: 1.2元
B40: 备注
C41: 1.以上价格单款一万个起包含运费不含税
C42: 2.付款方式：现结

Sheet 面纸开数
D1: 面纸长 | E1: 面纸宽
B2: =(铁盖纸筒核价表!C6*3.14+1)*10 -> 487.28 | C2: =铁盖纸筒核价表!D6*10+10 -> 320 | D2: =B2 -> 487.28 | E2: =C2 -> 320
B3: 1192 | C3: 889 | E3: =B3*C3 -> 1059688
B4: 1089 | C4: 787 | E4: =B4*C4 -> 857043
B8: 1 | C8: =TRUNC(B3/D2) -> 2 | E8: =B3-D2*C8 -> 217.44 | F8: =TRUNC(IF(E8>E2,C3/D2,0)) -> 0
B9: 2 | C9: =TRUNC(C3/E2) -> 2 | E9: =C3-E2*C9 -> 249 | F9: =TRUNC(IF(E9>D2,B3/E2,0)) -> 0
B10: 3 | C10: =C9*C8+F8+F9 -> 4
B11: 4 | C11: =TRUNC(C3/D2) -> 1 | E11: =C3-D2*C11 -> 401.72 | F11: =TRUNC(IF(E11>E2,B3/D2,0)) -> 2 | G11: =MAX(C10,C13) -> 5 | I11: =E3/G11 -> 211937.6
B12: 5 | C12: =TRUNC(B3/E2) -> 3 | E12: =B3-E2*C12 -> 232 | F12: =TRUNC(IF(E12>D2,C3/E2,0)) -> 0
B13: 6 | C13: =C11*C12+F11+F12 -> 5
K15: =IF(I19<I11,"正","大") -> 大 | L15: =IF(I19<I11,G19,G11) -> 5 | M15: =K16/L15 -> 0.22
B16: 1 | C16: =TRUNC(B4/D2) -> 2 | E16: =B4-D2*C16 -> 114.44 | F16: =TRUNC(IF(E16>E2,C4/D2,0)) -> 0 | K16: =IF(I19>I11,1.1,0.9) -> 1.1
B17: 2 | C17: =TRUNC(C4/E2) -> 2 | E17: =C4-E2*C17 -> 147 | F17: =TRUNC(IF(E17>D2,B4/E2,0)) -> 0
B18: 3 | C18: =C17*C16+F16+F17 -> 4
B19: 4 | C19: =TRUNC(C4/D2) -> 1 | E19: =C4-D2*C19 -> 299.72 | F19: =TRUNC(IF(E19>E2,B4/D2,0)) -> 0 | G19: =MAX(C18,C21) -> 4 | I19: =E4/G19 -> 214260.75
B20: 5 | C20: =TRUNC(B4/E2) -> 3 | E20: =B4-E2*C20 -> 129 | F20: =TRUNC(IF(E20>D2,C4/E2,0)) -> 0
B21: 6 | C21: =C19*C20+F20+F19 -> 3
D25: 面纸长 | E25: 面纸宽 | T25: 面纸长 | U25: 面纸宽
B26: =全纸筒核价表!F9*10 -> 300 | C26: =全纸筒核价表!G9*10 -> 360 | D26: =B26 -> 300 | E26: =C26 -> 360 | R26: =全纸筒核价表!F39*10 -> 340 | S26: =全纸筒核价表!G39*10 -> 270 | T26: =R26 -> 340 | U26: =S26 -> 270
B27: 1192 | C27: 889 | E27: =B27*C27 -> 1059688 | R27: 1192 | S27: 889 | U27: =R27*S27 -> 1059688
B28: 1089 | C28: 787 | E28: =B28*C28 -> 857043 | R28: 1089 | S28: 787 | U28: =R28*S28 -> 857043
B32: 1 | C32: =TRUNC(B27/D26) -> 3 | E32: =B27-D26*C32 -> 292 | F32: =TRUNC(IF(E32>E26,C27/D26,0)) -> 0 | R32: 1 | S32: =TRUNC(R27/T26) -> 3 | U32: =R27-T26*S32 -> 172 | V32: =TRUNC(IF(U32>U26,S27/T26,0)) -> 0
B33: 2 | C33: =TRUNC(C27/E26) -> 2 | E33: =C27-E26*C33 -> 169 | F33: =TRUNC(IF(E33>D26,B27/E26,0)) -> 0 | R33: 2 | S33: =TRUNC(S27/U26) -> 3 | U33: =S27-U26*S33 -> 79 | V33: =TRUNC(IF(U33>T26,R27/U26,0)) -> 0
B34: 3 | C34: =C33*C32+F32+F33 -> 6 | R34: 3 | S34: =S33*S32+V32+V33 -> 9
B35: 4 | C35: =TRUNC(C27/D26) -> 2 | E35: =C27-D26*C35 -> 289 | F35: =TRUNC(IF(E35>E26,B27/D26,0)) -> 0 | G35: =MAX(C34,C37) -> 6 | I35: =E27/G35 -> 176614.67 | R35: 4 | S35: =TRUNC(S27/T26) -> 2 | U35: =S27-T26*S35 -> 209 | V35: =TRUNC(IF(U35>U26,R27/T26,0)) -> 0 | W35: =MAX(S34,S37) -> 9 | Y35: =U27/W35 -> 117743.11
B36: 5 | C36: =TRUNC(B27/E26) -> 3 | E36: =B27-E26*C36 -> 112 | F36: =TRUNC(IF(E36>D26,C27/E26,0)) -> 0 | R36: 5 | S36: =TRUNC(R27/U26) -> 4 | U36: =R27-U26*S36 -> 112 | V36: =TRUNC(IF(U36>T26,S27/U26,0)) -> 0
B37: 6 | C37: =C35*C36+F35+F36 -> 6 | R37: 6 | S37: =S35*S36+V35+V36 -> 8
K39: =IF(I43<I35,"正规","大规") -> 正规 | L39: =IF(I43<I35,G43,G35) -> 6 | M39: =K40/L39 -> 0.15 | AA39: =IF(Y43<Y35,"正规","大规") -> 正规 | AB39: =IF(Y43<Y35,W43,W35) -> 8 | AC39: =AA40/AB39 -> 0.1125
B40: 1 | C40: =TRUNC(B28/D26) -> 3 | E40: =B28-D26*C40 -> 189 | F40: =TRUNC(IF(E40>E26,C28/D26,0)) -> 0 | K40: =IF(I43>I35,全纸筒核价表!J9,全纸筒核价表!K9) -> 0.9 | R40: 1 | S40: =TRUNC(R28/T26) -> 3 | U40: =R28-T26*S40 -> 69 | V40: =TRUNC(IF(U40>U26,S28/T26,0)) -> 0 | AA40: =IF(Y43>Y35,全纸筒核价表!J39,全纸筒核价表!K39) -> 0.9
B41: 2 | C41: =TRUNC(C28/E26) -> 2 | E41: =C28-E26*C41 -> 67 | F41: =TRUNC(IF(E41>D26,B28/E26,0)) -> 0 | R41: 2 | S41: =TRUNC(S28/U26) -> 2 | U41: =S28-U26*S41 -> 247 | V41: =TRUNC(IF(U41>T26,R28/U26,0)) -> 0
B42: 3 | C42: =C41*C40+F40+F41 -> 6 | R42: 3 | S42: =S41*S40+V40+V41 -> 6
B43: 4 | C43: =TRUNC(C28/D26) -> 2 | E43: =C28-D26*C43 -> 187 | F43: =TRUNC(IF(E43>E26,B28/D26,0)) -> 0 | G43: =MAX(C42,C45) -> 6 | I43: =E28/G43 -> 142840.5 | R43: 4 | S43: =TRUNC(S28/T26) -> 2 | U43: =S28-T26*S43 -> 107 | V43: =TRUNC(IF(U43>U26,R28/T26,0)) -> 0 | W43: =MAX(S42,S45) -> 8 | Y43: =U28/W43 -> 107130.38
B44: 5 | C44: =TRUNC(B28/E26) -> 3 | E44: =B28-E26*C44 -> 9 | F44: =TRUNC(IF(E44>D26,C28/E26,0)) -> 0 | R44: 5 | S44: =TRUNC(R28/U26) -> 4 | U44: =R28-U26*S44 -> 9 | V44: =TRUNC(IF(U44>T26,S28/U26,0)) -> 0
B45: 6 | C45: =C43*C44+F44+F43 -> 6 | R45: 6 | S45: =S43*S44+V44+V43 -> 8
A57: 计算器1
D60: 面纸长 | E60: 面纸宽
B61: =全纸筒核价表!S4*10 -> 370 | C61: =全纸筒核价表!T4*10 -> 340 | D61: =B61 -> 370 | E61: =C61 -> 340
B62: 1192 | C62: 889 | E62: =B62*C62 -> 1059688
B63: 1089 | C63: 787 | E63: =B63*C63 -> 857043
B67: 1 | C67: =TRUNC(B62/D61) -> 3 | E67: =B62-D61*C67 -> 82 | F67: =TRUNC(IF(E67>E61,C62/D61,0)) -> 0
...

Sheet 印面价格
D5: 直径 | E5: 圆周 | G5: 高度 | I5: 正规价格 | J5: 大规价格
D6: =铁盖纸筒核价表!C6*10 -> 152 | E6: =D6*3.1415 -> 477.508 | G6: =铁盖纸筒核价表!D6*10 -> 310 | I6: 0.9 | J6: 1.1
D8: 8开印刷机 | E8: 300
D9: 320 | E9: 505
E11: =E12*E6 -> 0 | F11: =E11+10 -> 10
D12: 320/圆周 | E12: =TRUNC(D9/E6) -> 0 | H12: =L41 -> 正规 | I12: =M41 -> 236
E13: =E14*G6 -> 310 | F13: =E13+10 -> 320
D14: 510/高度 | E14: =TRUNC(E9/G6) -> 1 | F14: 总开数 | G14: 面纸价格 | K14: 印面规格：
E15: =E12*E14 -> 0 | F15: =E15*M41 -> 0 | G15: =N41/E15 -> #DIV/0! | K15: 长度 | L15: 宽度
I16: =IF(G21<=G15,F21,F15) -> #DIV/0! | K16: =IF(G21<G15,F17,F11) -> #DIV/0! | L16: =IF(G21<G15,F19,F13) -> #DIV/0!
E17: =E18*E6 -> 477.508 | F17: =E17+10 -> 487.508 | K17: 拼几个： | L17: =IF(G21<=G15,E21,E15) -> #DIV/0!
D18: 510/圆周 | E18: =TRUNC(E9/E6) -> 1 | H18: =L66 -> 大规 | I18: =M66 -> 5 | K18: =IF(G21<=G15,L66,L41) -> #DIV/0! | L18: =IF(G21<G15,M66,M41) -> #DIV/0!
E19: =G6*E20 -> 310 | F19: =E19+10 -> 320
D20: 320/高度 | E20: =TRUNC(D9/G6) -> 1 | F20: 总开数 | G20: 面纸价格 | K20: 总共几张： | L20: =IF(G21<G15,F21,F15) -> #DIV/0!
E21: =E18*E20 -> 1 | F21: =M66*E21 -> 5 | G21: =N66/E21 -> 0.22 | K21: 单张价格 | L21: =IF(G21<G15,G21,G15) -> #DIV/0!
E27: 宽度 | F27: 长度
E28: =F11 -> 10 | F28: =F13 -> 320
C29: 1192 | D29: 889 | F29: =C29*D29 -> 1059688
C30: 1089 | D30: 787 | F30: =C30*D30 -> 857043
C34: 1 | D34: =TRUNC(C29/E28) -> 119 | F34: =C29-E28*D34 -> 2 | G34: =TRUNC(IF(F34>F28,D29/E28,0)) -> 0
C35: 2 | D35: =TRUNC(D29/F28) -> 2 | F35: =D29-F28*D35 -> 249 | G35: =TRUNC(IF(F35>E28,C29/F28,0)) -> 3
C36: 3 | D36: =D35*D34+G34+G35 -> 241
C37: 4 | D37: =TRUNC(D29/E28) -> 88 | F37: =D29-E28*D37 -> 9 | G37: =TRUNC(IF(F37>F28,C29/E28,0)) -> 0 | H37: =MAX(D36,D39) -> 266 | J37: =F29/H37 -> 3983.7895
C38: 5 | D38: =TRUNC(C29/F28) -> 3 | F38: =C29-F28*D38 -> 232 | G38: =TRUNC(IF(F38>E28,D29/F28,0)) -> 2
C39: 6 | D39: =D37*D38+G37+G38 -> 266
L41: =IF(J45<J37,"正规","大规") -> 正规 | M41: =IF(J45<J37,H45,H37) -> 236 | N41: =L42/M41 -> 0.0038135593
C42: 1 | D42: =TRUNC(C30/E28) -> 108 | F42: =C30-E28*D42 -> 9 | G42: =TRUNC(IF(F42>F28,D30/E28,0)) -> 0 | L42: =IF(J45>J37,J6,I6) -> 0.9
C43: 2 | D43: =TRUNC(D30/F28) -> 2 | F43: =D30-F28*D43 -> 147 | G43: =TRUNC(IF(F43>E28,C30/F28,0)) -> 3
C44: 3 | D44: =D43*D42+G42+G43 -> 219
C45: 4 | D45: =TRUNC(D30/E28) -> 78 | F45: =D30-E28*D45 -> 7 | G45: =TRUNC(IF(F45>F28,C30/E28,0)) -> 0 | H45: =MAX(D44,D47) -> 236 | J45: =F30/H45 -> 3631.5381
C46: 5 | D46: =TRUNC(C30/F28) -> 3 | F46: =C30-F28*D46 -> 129 | G46: =TRUNC(IF(F46>E28,D30/F28,0)) -> 2
C47: 6 | D47: =D45*D46+G46+G45 -> 236
E52: 宽度 | F52: 长度
E53: =F17 -> 487.508 | F53: =F19 -> 320
C54: 1192 | D54: 889 | F54: =C54*D54 -> 1059688
C55: 1089 | D55: 787 | F55: =C55*D55 -> 857043
C59: 1 | D59: =TRUNC(C54/E53) -> 2 | F59: =C54-E53*D59 -> 216.984 | G59: =TRUNC(IF(F59>F53,D54/E53,0)) -> 0
C60: 2 | D60: =TRUNC(D54/F53) -> 2 | F60: =D54-F53*D60 -> 249 | G60: =TRUNC(IF(F60>E53,C54/F53,0)) -> 0
C61: 3 | D61: =D60*D59+G59+G60 -> 4
C62: 4 | D62: =TRUNC(D54/E53) -> 1 | F62: =D54-E53*D62 -> 401.492 | G62: =TRUNC(IF(F62>F53,C54/E53,0)) -> 2 | H62: =MAX(D61,D64) -> 5 | J62: =F54/H62 -> 211937.6
...

Sheet 印面价格2

Sheet 各类纸筒价格对比表
